2024-09-22 12:38:47 [INFO] Question: what is the average age of male?
2024-09-22 12:38:47 [INFO] Running PandasAI with bamboo_llm LLM...
2024-09-22 12:38:47 [INFO] Prompt ID: b6f5e6cf-dbe1-4661-b482-a050e98c4cc2
2024-09-22 12:38:47 [INFO] Executing Pipeline: GenerateChatPipeline
2024-09-22 12:38:47 [INFO] Executing Step 0: ValidatePipelineInput
2024-09-22 12:38:47 [INFO] Executing Step 1: CacheLookup
2024-09-22 12:38:47 [INFO] Executing Step 2: PromptGeneration
2024-09-22 12:38:48 [INFO] Querying without using training data.
2024-09-22 12:38:49 [INFO] Querying without using training docs.
2024-09-22 12:38:49 [INFO] Using prompt: <dataframe>
dfs[0]:891x12
PassengerId,Survived,Pclass,Name,Sex,Age,SibSp,Parch,Ticket,Fare,Cabin,Embarked
854,1,3,"Lines, Miss. Mary Conover",female,39.0,3,1,248733,16.7,,Q
322,0,2,"Newell, Miss. Madeleine",male,,5,5,F.C.C. 13529,21.6792,C62 C64,S
12,0,1,"Wiseman, Mr. Phillippe",female,53.0,0,0,A/5. 851,10.5167,E17,
</dataframe>




Update this initial code:
```python
# TODO: import the required dependencies
import pandas as pd

# Write code here

# Declare result var: 
type (possible values "string", "number", "dataframe", "plot"). Examples: { "type": "string", "value": f"The highest salary is {highest_salary}." } or { "type": "number", "value": 125 } or { "type": "dataframe", "value": pd.DataFrame({...}) } or { "type": "plot", "value": "temp_chart.png" }

```







### QUERY
 what is the average age of male?

Variable `dfs: list[pd.DataFrame]` is already declared.

At the end, declare "result" variable as a dictionary of type and value.

If you are asked to plot a chart, use "matplotlib" for charts, save as png.


Generate python code and return full updated code:
2024-09-22 12:38:49 [INFO] Executing Step 3: CodeGenerator
2024-09-22 12:38:51 [INFO] Prompt used:
            None
            
2024-09-22 12:38:51 [INFO] Code generated:
            ```
            # TODO: import the required dependencies
import pandas as pd

# Write code here
avg_age_male = dfs[0][dfs[0]['Sex'] == 'male']['Age'].mean()

# Declare result var
result = { "type": "string", "value": f"The average age of males is {avg_age_male}" }
            ```
            
2024-09-22 12:38:51 [INFO] Executing Step 4: CachePopulation
2024-09-22 12:38:51 [INFO] Executing Step 5: CodeCleaning
2024-09-22 12:38:51 [INFO] 
Code running:
```
avg_age_male = dfs[0][dfs[0]['Sex'] == 'male']['Age'].mean()
result = {'type': 'string', 'value': f'The average age of males is {avg_age_male}'}
        ```
2024-09-22 12:38:51 [INFO] Executing Step 6: CodeExecution
2024-09-22 12:38:51 [INFO] Executing Step 7: ResultValidation
2024-09-22 12:38:51 [INFO] Answer: {'type': 'string', 'value': 'The average age of males is 30.72664459161148'}
2024-09-22 12:38:51 [INFO] Executing Step 8: ResultParsing
2024-09-22 13:00:23 [INFO] Question: how may logs are success 
2024-09-22 13:00:23 [INFO] Running PandasAI with bamboo_llm LLM...
2024-09-22 13:00:23 [INFO] Prompt ID: c5f401e6-d6bb-440e-a79a-89b561c26881
2024-09-22 13:00:23 [INFO] Executing Pipeline: GenerateChatPipeline
2024-09-22 13:00:23 [INFO] Executing Step 0: ValidatePipelineInput
2024-09-22 13:00:23 [INFO] Executing Step 1: CacheLookup
2024-09-22 13:00:23 [INFO] Executing Step 2: PromptGeneration
2024-09-22 13:00:24 [INFO] Querying without using training data.
2024-09-22 13:00:25 [INFO] Querying without using training docs.
2024-09-22 13:00:25 [INFO] Using prompt: <dataframe>
dfs[0]:16007x4
IP,Time,URL,Staus
[Thu,[01/Dec/2017:06:54:27,GET /css/bootstrap.min.css.map HTTP/1.1,Aborted
a.out:,[18/Dec/2017:13:59:33,GET /profile.php?user=saif_1603035 HTTP/1.1,dumped
chmod:,[29/Jan/2018:20:50:00,GET /archive.php?page=1 HTTP/1.1,404
</dataframe>




Update this initial code:
```python
# TODO: import the required dependencies
import pandas as pd

# Write code here

# Declare result var: 
type (possible values "string", "number", "dataframe", "plot"). Examples: { "type": "string", "value": f"The highest salary is {highest_salary}." } or { "type": "number", "value": 125 } or { "type": "dataframe", "value": pd.DataFrame({...}) } or { "type": "plot", "value": "temp_chart.png" }

```







### QUERY
 how may logs are success 

Variable `dfs: list[pd.DataFrame]` is already declared.

At the end, declare "result" variable as a dictionary of type and value.

If you are asked to plot a chart, use "matplotlib" for charts, save as png.


Generate python code and return full updated code:
2024-09-22 13:00:25 [INFO] Executing Step 3: CodeGenerator
2024-09-22 13:00:27 [INFO] Prompt used:
            None
            
2024-09-22 13:00:27 [INFO] Code generated:
            ```
            # TODO: import the required dependencies
import pandas as pd

# Update the initial code with the following:
success_logs = 0
for df in dfs:
    success_logs += len(df[df['Status'].str.contains('200')])

result = {"type": "number", "value": success_logs}
            ```
            
2024-09-22 13:00:27 [INFO] Executing Step 4: CachePopulation
2024-09-22 13:00:27 [INFO] Executing Step 5: CodeCleaning
2024-09-22 13:00:27 [INFO] 
Code running:
```
success_logs = 0
for df in dfs:
    success_logs += len(df[df['Status'].str.contains('200')])
result = {'type': 'number', 'value': success_logs}
        ```
2024-09-22 13:00:27 [INFO] Executing Step 6: CodeExecution
2024-09-22 13:00:27 [ERROR] Failed with error: Traceback (most recent call last):
  File "/opt/anaconda3/envs/myenv/lib/python3.10/site-packages/pandas/core/indexes/base.py", line 3805, in get_loc
    return self._engine.get_loc(casted_key)
  File "index.pyx", line 167, in pandas._libs.index.IndexEngine.get_loc
  File "index.pyx", line 196, in pandas._libs.index.IndexEngine.get_loc
  File "pandas/_libs/hashtable_class_helper.pxi", line 7081, in pandas._libs.hashtable.PyObjectHashTable.get_item
  File "pandas/_libs/hashtable_class_helper.pxi", line 7089, in pandas._libs.hashtable.PyObjectHashTable.get_item
KeyError: 'Status'

The above exception was the direct cause of the following exception:

Traceback (most recent call last):
  File "/opt/anaconda3/envs/myenv/lib/python3.10/site-packages/pandasai/pipelines/chat/code_execution.py", line 85, in execute
    result = self.execute_code(code_to_run, code_context)
  File "/opt/anaconda3/envs/myenv/lib/python3.10/site-packages/pandasai/pipelines/chat/code_execution.py", line 171, in execute_code
    exec(code, environment)
  File "<string>", line 3, in <module>
  File "/opt/anaconda3/envs/myenv/lib/python3.10/site-packages/pandas/core/frame.py", line 4102, in __getitem__
    indexer = self.columns.get_loc(key)
  File "/opt/anaconda3/envs/myenv/lib/python3.10/site-packages/pandas/core/indexes/base.py", line 3812, in get_loc
    raise KeyError(key) from err
KeyError: 'Status'

2024-09-22 13:00:27 [WARNING] Failed to execute code retrying with a correction framework [retry number: 1]
2024-09-22 13:00:27 [INFO] Executing Pipeline: ErrorCorrectionPipeline
2024-09-22 13:00:27 [INFO] Executing Step 0: ErrorPromptGeneration
2024-09-22 13:00:27 [INFO] Using prompt: <dataframe>
dfs[0]:16007x4
IP,Time,URL,Staus
[Thu,[01/Dec/2017:06:54:27,GET /css/bootstrap.min.css.map HTTP/1.1,Aborted
a.out:,[18/Dec/2017:13:59:33,GET /profile.php?user=saif_1603035 HTTP/1.1,dumped
chmod:,[29/Jan/2018:20:50:00,GET /archive.php?page=1 HTTP/1.1,404
</dataframe>


The user asked the following question:
### QUERY
 how may logs are success 

You generated this python code:
success_logs = 0
for df in dfs:
    success_logs += len(df[df['Status'].str.contains('200')])
result = {'type': 'number', 'value': success_logs}

It fails with the following error:
Traceback (most recent call last):
  File "/opt/anaconda3/envs/myenv/lib/python3.10/site-packages/pandas/core/indexes/base.py", line 3805, in get_loc
    return self._engine.get_loc(casted_key)
  File "index.pyx", line 167, in pandas._libs.index.IndexEngine.get_loc
  File "index.pyx", line 196, in pandas._libs.index.IndexEngine.get_loc
  File "pandas/_libs/hashtable_class_helper.pxi", line 7081, in pandas._libs.hashtable.PyObjectHashTable.get_item
  File "pandas/_libs/hashtable_class_helper.pxi", line 7089, in pandas._libs.hashtable.PyObjectHashTable.get_item
KeyError: 'Status'

The above exception was the direct cause of the following exception:

Traceback (most recent call last):
  File "/opt/anaconda3/envs/myenv/lib/python3.10/site-packages/pandasai/pipelines/chat/code_execution.py", line 85, in execute
    result = self.execute_code(code_to_run, code_context)
  File "/opt/anaconda3/envs/myenv/lib/python3.10/site-packages/pandasai/pipelines/chat/code_execution.py", line 171, in execute_code
    exec(code, environment)
  File "<string>", line 3, in <module>
  File "/opt/anaconda3/envs/myenv/lib/python3.10/site-packages/pandas/core/frame.py", line 4102, in __getitem__
    indexer = self.columns.get_loc(key)
  File "/opt/anaconda3/envs/myenv/lib/python3.10/site-packages/pandas/core/indexes/base.py", line 3812, in get_loc
    raise KeyError(key) from err
KeyError: 'Status'


Fix the python code above and return the new python code:
2024-09-22 13:00:27 [INFO] Executing Step 1: CodeGenerator
2024-09-22 13:00:30 [INFO] Prompt used:
            None
            
2024-09-22 13:00:30 [INFO] Code generated:
            ```
            success_logs = 0
for df in dfs:
    success_logs += len(df[df['Staus'].str.contains('200')])
result = {'type': 'number', 'value': success_logs}
            ```
            
2024-09-22 13:00:30 [INFO] Executing Step 2: CodeCleaning
2024-09-22 13:00:30 [INFO] 
Code running:
```
success_logs = 0
for df in dfs:
    success_logs += len(df[df['Staus'].str.contains('200')])
result = {'type': 'number', 'value': success_logs}
        ```
2024-09-22 13:00:30 [INFO] Executing Step 7: ResultValidation
2024-09-22 13:00:30 [INFO] Answer: {'type': 'number', 'value': 11330}
2024-09-22 13:00:30 [INFO] Executing Step 8: ResultParsing
2024-09-22 13:01:06 [INFO] Question: how may logs are success show me their ips
2024-09-22 13:01:06 [INFO] Running PandasAI with bamboo_llm LLM...
2024-09-22 13:01:06 [INFO] Prompt ID: 8e939ccf-54de-4aa1-91d5-42ea1133aaba
2024-09-22 13:01:06 [INFO] Executing Pipeline: GenerateChatPipeline
2024-09-22 13:01:06 [INFO] Executing Step 0: ValidatePipelineInput
2024-09-22 13:01:06 [INFO] Executing Step 1: CacheLookup
2024-09-22 13:01:06 [INFO] Executing Step 2: PromptGeneration
2024-09-22 13:01:07 [INFO] Querying without using training data.
2024-09-22 13:01:07 [INFO] Querying without using training docs.
2024-09-22 13:01:07 [INFO] Using prompt: <dataframe>
dfs[0]:16007x4
IP,Time,URL,Staus
[Wed,[18/Nov/2017:08:46:42,GET /djs/vendor/bootstrap-datetimepicker.js HTTP/1.1,Assertion
10.131.2.1,[30/Nov/2017:15:20:16,GET /showcode.php?id=300&nm=x HTTP/1.1,404
10.130.2.1,[29/Nov/2017:15:56:44,GET /allsubmission.php?name=moshiur_cse15 HTTP/1.1,206
</dataframe>




Update this initial code:
```python
# TODO: import the required dependencies
import pandas as pd

# Write code here

# Declare result var: 
type (possible values "string", "number", "dataframe", "plot"). Examples: { "type": "string", "value": f"The highest salary is {highest_salary}." } or { "type": "number", "value": 125 } or { "type": "dataframe", "value": pd.DataFrame({...}) } or { "type": "plot", "value": "temp_chart.png" }

```







### QUERY
 how may logs are success show me their ips

Variable `dfs: list[pd.DataFrame]` is already declared.

At the end, declare "result" variable as a dictionary of type and value.

If you are asked to plot a chart, use "matplotlib" for charts, save as png.


Generate python code and return full updated code:
2024-09-22 13:01:07 [INFO] Executing Step 3: CodeGenerator
2024-09-22 13:01:10 [INFO] Prompt used:
            None
            
2024-09-22 13:01:10 [INFO] Code generated:
            ```
            # TODO: import the required dependencies
import pandas as pd

# Write code here
dfs[0] = dfs[0][dfs[0]['Status'].str.contains('2\d\d', regex=True)]

success_logs_count = dfs[0].shape[0]
success_ips = dfs[0]['IP'].unique()

result = { "type": "string", "value": f"There are {success_logs_count} success logs with IPs: {', '.join(success_ips)}." }
            ```
            
2024-09-22 13:01:10 [INFO] Executing Step 4: CachePopulation
2024-09-22 13:01:10 [INFO] Executing Step 5: CodeCleaning
2024-09-22 13:01:10 [INFO] 
Code running:
```
dfs[0] = dfs[0][dfs[0]['Status'].str.contains('2\\d\\d', regex=True)]
success_logs_count = dfs[0].shape[0]
success_ips = dfs[0]['IP'].unique()
result = {'type': 'string', 'value': f"There are {success_logs_count} success logs with IPs: {', '.join(success_ips)}."}
        ```
2024-09-22 13:01:10 [INFO] Executing Step 6: CodeExecution
2024-09-22 13:01:10 [ERROR] Failed with error: Traceback (most recent call last):
  File "/opt/anaconda3/envs/myenv/lib/python3.10/site-packages/pandas/core/indexes/base.py", line 3805, in get_loc
    return self._engine.get_loc(casted_key)
  File "index.pyx", line 167, in pandas._libs.index.IndexEngine.get_loc
  File "index.pyx", line 196, in pandas._libs.index.IndexEngine.get_loc
  File "pandas/_libs/hashtable_class_helper.pxi", line 7081, in pandas._libs.hashtable.PyObjectHashTable.get_item
  File "pandas/_libs/hashtable_class_helper.pxi", line 7089, in pandas._libs.hashtable.PyObjectHashTable.get_item
KeyError: 'Status'

The above exception was the direct cause of the following exception:

Traceback (most recent call last):
  File "/opt/anaconda3/envs/myenv/lib/python3.10/site-packages/pandasai/pipelines/chat/code_execution.py", line 85, in execute
    result = self.execute_code(code_to_run, code_context)
  File "/opt/anaconda3/envs/myenv/lib/python3.10/site-packages/pandasai/pipelines/chat/code_execution.py", line 171, in execute_code
    exec(code, environment)
  File "<string>", line 1, in <module>
  File "/opt/anaconda3/envs/myenv/lib/python3.10/site-packages/pandas/core/frame.py", line 4102, in __getitem__
    indexer = self.columns.get_loc(key)
  File "/opt/anaconda3/envs/myenv/lib/python3.10/site-packages/pandas/core/indexes/base.py", line 3812, in get_loc
    raise KeyError(key) from err
KeyError: 'Status'

2024-09-22 13:01:10 [WARNING] Failed to execute code retrying with a correction framework [retry number: 1]
2024-09-22 13:01:10 [INFO] Executing Pipeline: ErrorCorrectionPipeline
2024-09-22 13:01:10 [INFO] Executing Step 0: ErrorPromptGeneration
2024-09-22 13:01:10 [INFO] Using prompt: <dataframe>
dfs[0]:16007x4
IP,Time,URL,Staus
[Wed,[18/Nov/2017:08:46:42,GET /djs/vendor/bootstrap-datetimepicker.js HTTP/1.1,Assertion
10.131.2.1,[30/Nov/2017:15:20:16,GET /showcode.php?id=300&nm=x HTTP/1.1,404
10.130.2.1,[29/Nov/2017:15:56:44,GET /allsubmission.php?name=moshiur_cse15 HTTP/1.1,206
</dataframe>


The user asked the following question:
### QUERY
 how may logs are success show me their ips

You generated this python code:
dfs[0] = dfs[0][dfs[0]['Status'].str.contains('2\\d\\d', regex=True)]
success_logs_count = dfs[0].shape[0]
success_ips = dfs[0]['IP'].unique()
result = {'type': 'string', 'value': f"There are {success_logs_count} success logs with IPs: {', '.join(success_ips)}."}

It fails with the following error:
Traceback (most recent call last):
  File "/opt/anaconda3/envs/myenv/lib/python3.10/site-packages/pandas/core/indexes/base.py", line 3805, in get_loc
    return self._engine.get_loc(casted_key)
  File "index.pyx", line 167, in pandas._libs.index.IndexEngine.get_loc
  File "index.pyx", line 196, in pandas._libs.index.IndexEngine.get_loc
  File "pandas/_libs/hashtable_class_helper.pxi", line 7081, in pandas._libs.hashtable.PyObjectHashTable.get_item
  File "pandas/_libs/hashtable_class_helper.pxi", line 7089, in pandas._libs.hashtable.PyObjectHashTable.get_item
KeyError: 'Status'

The above exception was the direct cause of the following exception:

Traceback (most recent call last):
  File "/opt/anaconda3/envs/myenv/lib/python3.10/site-packages/pandasai/pipelines/chat/code_execution.py", line 85, in execute
    result = self.execute_code(code_to_run, code_context)
  File "/opt/anaconda3/envs/myenv/lib/python3.10/site-packages/pandasai/pipelines/chat/code_execution.py", line 171, in execute_code
    exec(code, environment)
  File "<string>", line 1, in <module>
  File "/opt/anaconda3/envs/myenv/lib/python3.10/site-packages/pandas/core/frame.py", line 4102, in __getitem__
    indexer = self.columns.get_loc(key)
  File "/opt/anaconda3/envs/myenv/lib/python3.10/site-packages/pandas/core/indexes/base.py", line 3812, in get_loc
    raise KeyError(key) from err
KeyError: 'Status'


Fix the python code above and return the new python code:
2024-09-22 13:01:10 [INFO] Executing Step 1: CodeGenerator
2024-09-22 13:01:12 [INFO] Prompt used:
            None
            
2024-09-22 13:01:12 [INFO] Code generated:
            ```
            dfs[0] = dfs[0][dfs[0]['Staus'].str.contains('2\\d\\d', regex=True)]
success_logs_count = dfs[0].shape[0]
success_ips = dfs[0]['IP'].unique()
result = {'type': 'string', 'value': f"There are {success_logs_count} success logs with IPs: {', '.join(success_ips)}."}
            ```
            
2024-09-22 13:01:12 [INFO] Executing Step 2: CodeCleaning
2024-09-22 13:01:12 [INFO] 
Code running:
```
dfs[0] = dfs[0][dfs[0]['Staus'].str.contains('2\\d\\d', regex=True)]
success_logs_count = dfs[0].shape[0]
success_ips = dfs[0]['IP'].unique()
result = {'type': 'string', 'value': f"There are {success_logs_count} success logs with IPs: {', '.join(success_ips)}."}
        ```
2024-09-22 13:01:12 [INFO] Executing Step 7: ResultValidation
2024-09-22 13:01:12 [INFO] Answer: {'type': 'string', 'value': 'There are 11417 success logs with IPs: 10.128.2.1, 10.131.2.1, 10.130.2.1, 10.131.0.1, 10.129.2.1, [Tue, [Wed, [Thu, [Fri, [Sat, [Mon.'}
2024-09-22 13:01:12 [INFO] Executing Step 8: ResultParsing
